[
    {
        "id": "log_20250212_090000",
        "timestamp": "2025-02-12 09:00:00",
        "error": "Database connection timeout",
        "stack_trace": "File 'test_db_handler.py', line 9, in connect_to_database",
        "fix_attempted": "def fix_database_timeout():\n    try:\n        from sqlalchemy import create_engine\n        from sqlalchemy.exc import OperationalError\n        \n        engine = create_engine('your-db-uri')  # replace with your db uri\n        connection = engine.connect()\n        if connection is not None:\n            return True\n    except OperationalError as e:\n        print(f\"Database Connection Failed: {str(e)}\")\n        return False\n",
        "fix_successful": "Pending Human Verification",
        "execution_time": 30.12,
        "resolved": true
    },
    {
        "id": "log_20250212_090500",
        "timestamp": "2025-02-12 09:05:00",
        "error": "NameError: name 'model' is not defined",
        "stack_trace": "File 'test_api_handler.py', line 8, in predict",
        "fix_attempted": "from flask import Flask, request, jsonify\nimport joblib\n\napp = Flask(__name__)\nmodel = joblib.load('path/to/your_model.pkl')\n\n@app.route('/predict', methods=['POST'])\ndef predict():\n    data = request.get_json()\n    result = model.predict(data[\"input\"])\n    return jsonify({\"prediction\": result})\n\nif __name__ == \"__main__\":\n    app.run(debug=True)",
        "fix_successful": true,
        "execution_time": 28.5,
        "resolved": true
    },
    {
        "id": "log_20250212_091000",
        "timestamp": "2025-02-12 09:10:00",
        "error": "ZeroDivisionError: division by zero",
        "stack_trace": "File 'test_math_operations.py', line 6, in divide_numbers",
        "fix_attempted": "def divide_numbers(a, b):\n    \"\"\"Performs division but does not handle zero division.\"\"\"\n    if b != 0:\n        return a / b\n    else:\n        print(\"Error: Division by zero\")\n        return None",
        "fix_successful": true,
        "execution_time": 25.88,
        "resolved": true
    },
    {
        "id": "fix_20250212_111318",
        "timestamp": "2025-02-12 11:13:18",
        "original_log_id": "log_20250212_091000",
        "file_modified": "test_math_operations.py",
        "applied_fix": "def safe_divide(n, d):\n    try:\n        return n / d\n    except ZeroDivisionError:\n        return 0",
        "status": "Fix Verified",
        "fix_successful": true
    },
    {
        "id": "log_20250212_130000",
        "timestamp": "2025-02-12 13:00:00",
        "error": "Database connection timeout",
        "stack_trace": "File 'test_db_handler.py', line 15, in connect_to_database",
        "fix_attempted": "```python\ndef set_database_connection_timeout():\n    engine = create_engine('your-db-uri', connect_args={\"connect_timeout\": 120}) # Increased timeout\n```",
        "fix_successful": true,
        "execution_time": null,
        "resolved": true
    },
    {
        "id": "log_20250212_131500",
        "timestamp": "2025-02-12 13:15:00",
        "error": "KeyError: 'username'",
        "stack_trace": "File 'user_auth.py', line 22, in authenticate_user",
        "fix_attempted": "```python\ndef authenticate_user(user_data):\n    \"\"\"Authenticates a user but throws KeyError if 'username' is missing.\"\"\"\n    return user_data.get(\"username\")  # \u2705 No more KeyError if 'username' is missing\n```",
        "fix_successful": true,
        "execution_time": null,
        "resolved": true
    },
    {
        "id": "log_20250212_133000",
        "timestamp": "2025-02-12 13:30:00",
        "error": "ZeroDivisionError: division by zero",
        "stack_trace": "File 'math_utilities.py', line 10, in calculate_ratio",
        "fix_attempted": "```python\ndef calculate_ratio(numerator, denominator):\n    if denominator == 0:\n        return 'denominator is zero'\n    else:\n        return numerator / denominator\n```",
        "fix_successful": true,
        "execution_time": null,
        "resolved": true
    },
    {
        "id": "log_20250212_134500",
        "timestamp": "2025-02-12 13:45:00",
        "error": "TypeError: unsupported operand type(s) for +: 'int' and 'NoneType'",
        "stack_trace": "File 'data_processor.py', line 37, in process_data",
        "fix_attempted": "```python\ndef process_data(input_data):\n    \"\"\"Processes data and handles NoneType values.\"\"\"\n    if input_data[\"value\"] is not None:\n        return input_data[\"value\"] + 10\n    else:\n        return 10\n```",
        "fix_successful": true,
        "execution_time": null,
        "resolved": true
    }
]